Workbook
Name ave: KPIs!$Q$2
Name average: #REF!
Name coupon: Trends_Calculator!$K$13
Name least: KPIs!$H$5
Name max: #REF!
Name min: #REF!
Name pay: Trends_Calculator!$D$13
Name product: KPIs!$H$3
Name quantity: KPIs!$S$2
Name refer: Trends_Calculator!$S$13
Name Slicer_Year: #N/A
Name total: KPIs!$L$2
Name year: Trends_Calculator!$D$13

Sheet Raw Data
A1: OrderID | B1: Date | C1: CustomerID | D1: Product | E1: Quantity | F1: UnitPrice | G1: ShippingAddress | H1: PaymentMethod | I1: OrderStatus | J1: TrackingNumber | K1: ItemsInCart | L1: CouponCode | M1: ReferralSource | N1: TotalPrice
A2: ORD200000 | B2: 44930 | C2: C72649 | D2: Monitor | E2: 5 | F2: 570.62 | G2: 928 Main St | H2: Debit Card | I2: Shipped | J2: TRK37947903 | K2: 7 | L2: SAVE10 | M2: Instagram | N2: 2853.1
A3: ORD200001 | B3: 45527 | C3: C75739 | D3: Phone | E3: 2 | F3: 151.35 | G3: 823 Main St | H3: Online | I3: Shipped | J3: TRK91186779 | K3: 3 | L3: SAVE10 | M3: Referral | N3: 302.7
A4: ORD200002 | B4: 45349 | C4: C81728 | D4: Tablet | E4: 5 | F4: 550.68 | G4: 512 Main St | H4: Credit Card | I4: Cancelled | J4: TRK42903982 | K4: 8 | L4: FREESHIP | M4: Email | N4: 2753.4
A5: ORD200003 | B5: 45214 | C5: C33540 | D5: Chair | E5: 1 | F5: 273.19 | G5: 275 Main St | H5: Debit Card | I5: Returned | J5: TRK62788070 | K5: 5 | L5: SAVE10 | M5: Facebook | N5: 273.19
A6: ORD200004 | B6: 45785 | C6: C81840 | D6: Printer | E6: 4 | F6: 626.01 | G6: 668 Main St | H6: Online | I6: Delivered | J6: TRK29241424 | K6: 8 | L6: SAVE10 | M6: Email | N6: 2504.04
A7: ORD200005 | B7: 45222 | C7: C37249 | D7: Phone | E7: 2 | F7: 245.86 | G7: 934 Main St | H7: Credit Card | I7: Shipped | J7: TRK72976927 | K7: 4 | L7: SAVE10 | M7: Instagram | N7: 491.72
A8: ORD200006 | B8: 45825 | C8: C83492 | D8: Laptop | E8: 1 | F8: 664.42 | G8: 986 Main St | H8: Gift Card | I8: Returned | J8: TRK96417362 | K8: 6 | L8: SAVE10 | M8: Facebook | N8: 664.42
A9: ORD200007 | B9: 45058 | C9: C41460 | D9: Monitor | E9: 5 | F9: 149.55 | G9: 706 Main St | H9: Cash | I9: Shipped | J9: TRK78809193 | K9: 9 | L9: FREESHIP | M9: Facebook | N9: 747.75
A10: ORD200008 | B10: 45749 | C10: C26817 | D10: Phone | E10: 2 | F10: 134.28 | G10: 904 Main St | H10: Gift Card | I10: Cancelled | J10: TRK61042692 | K10: 2 | M10: Email | N10: 268.56
A11: ORD200009 | B11: 45251 | C11: C31946 | D11: Desk | E11: 4 | F11: 509.38 | G11: 102 Main St | H11: Credit Card | I11: Shipped | J11: TRK33478363 | K11: 6 | L11: SAVE10 | M11: Google | N11: 2037.52
A12: ORD200010 | B12: 45289 | C12: C43443 | D12: Tablet | E12: 5 | F12: 625.97 | G12: 333 Main St | H12: Credit Card | I12: Returned | J12: TRK98859248 | K12: 9 | L12: WINTER15 | M12: Instagram | N12: 3129.85
A13: ORD200011 | B13: 45339 | C13: C93861 | D13: Monitor | E13: 3 | F13: 49.14 | G13: 831 Main St | H13: Online | I13: Returned | J13: TRK48234646 | K13: 7 | L13: SAVE10 | M13: Email | N13: 147.42
A14: ORD200012 | B14: 45580 | C14: C38785 | D14: Monitor | E14: 2 | F14: 180.5 | G14: 179 Main St | H14: Debit Card | I14: Pending | J14: TRK20419991 | K14: 6 | L14: FREESHIP | M14: Referral | N14: 361
A15: ORD200013 | B15: 45168 | C15: C88348 | D15: Laptop | E15: 3 | F15: 201.49 | G15: 903 Main St | H15: Credit Card | I15: Returned | J15: TRK81913874 | K15: 4 | L15: FREESHIP | M15: Facebook | N15: 604.47
A16: ORD200014 | B16: 45012 | C16: C98474 | D16: Tablet | E16: 2 | F16: 393.33 | G16: 980 Main St | H16: Debit Card | I16: Pending | J16: TRK79186539 | K16: 3 | L16: SAVE10 | M16: Instagram | N16: 786.66
A17: ORD200015 | B17: 45124 | C17: C39416 | D17: Printer | E17: 1 | F17: 473.96 | G17: 942 Main St | H17: Cash | I17: Delivered | J17: TRK54930938 | K17: 3 | M17: Google | N17: 473.96
A18: ORD200016 | B18: 44950 | C18: C28976 | D18: Printer | E18: 2 | F18: 533.81 | G18: 914 Main St | H18: Credit Card | I18: Pending | J18: TRK13194259 | K18: 3 | L18: FREESHIP | M18: Email | N18: 1067.62
A19: ORD200017 | B19: 45353 | C19: C60672 | D19: Tablet | E19: 1 | F19: 423.4 | G19: 382 Main St | H19: Debit Card | I19: Shipped | J19: TRK11972116 | K19: 3 | M19: Referral | N19: 423.4
A20: ORD200018 | B20: 45742 | C20: C84329 | D20: Desk | E20: 1 | F20: 431.44 | G20: 891 Main St | H20: Gift Card | I20: Pending | J20: TRK65191045 | K20: 3 | L20: SAVE10 | M20: Facebook | N20: 431.44
A21: ORD200019 | B21: 44949 | C21: C14552 | D21: Monitor | E21: 5 | F21: 224 | G21: 273 Main St | H21: Cash | I21: Returned | J21: TRK59101365 | K21: 9 | L21: SAVE10 | M21: Google | N21: 1120
A22: ORD200020 | B22: 45054 | C22: C54829 | D22: Chair | E22: 5 | F22: 62.51 | G22: 587 Main St | H22: Cash | I22: Pending | J22: TRK16718651 | K22: 9 | L22: WINTER15 | M22: Instagram | N22: 312.55
A23: ORD200021 | B23: 45613 | C23: C99023 | D23: Monitor | E23: 4 | F23: 342.95 | G23: 569 Main St | H23: Cash | I23: Delivered | J23: TRK52646983 | K23: 6 | M23: Google | N23: 1371.8
A24: ORD200022 | B24: 44955 | C24: C34416 | D24: Monitor | E24: 2 | F24: 49.62 | G24: 633 Main St | H24: Online | I24: Pending | J24: TRK75937350 | K24: 2 | L24: SAVE10 | M24: Google | N24: 99.24
A25: ORD200023 | B25: 45756 | C25: C42372 | D25: Phone | E25: 4 | F25: 273.25 | G25: 755 Main St | H25: Debit Card | I25: Cancelled | J25: TRK36168083 | K25: 5 | L25: FREESHIP | M25: Referral | N25: 1093
A26: ORD200024 | B26: 45595 | C26: C17470 | D26: Laptop | E26: 2 | F26: 230.95 | G26: 956 Main St | H26: Online | I26: Delivered | J26: TRK28775057 | K26: 3 | L26: WINTER15 | M26: Referral | N26: 461.9
A27: ORD200025 | B27: 45497 | C27: C42577 | D27: Monitor | E27: 1 | F27: 399.98 | G27: 709 Main St | H27: Debit Card | I27: Delivered | J27: TRK69423327 | K27: 3 | L27: WINTER15 | M27: Email | N27: 399.98
A28: ORD200026 | B28: 45357 | C28: C21944 | D28: Laptop | E28: 5 | F28: 59.55 | G28: 296 Main St | H28: Online | I28: Delivered | J28: TRK80276812 | K28: 6 | M28: Referral | N28: 297.75
A29: ORD200027 | B29: 45344 | C29: C97593 | D29: Printer | E29: 1 | F29: 472.74 | G29: 881 Main St | H29: Online | I29: Shipped | J29: TRK89117573 | K29: 6 | L29: WINTER15 | M29: Google | N29: 472.74
A30: ORD200028 | B30: 45251 | C30: C59823 | D30: Phone | E30: 4 | F30: 160.07 | G30: 568 Main St | H30: Online | I30: Pending | J30: TRK65895539 | K30: 5 | M30: Email | N30: 640.28
A31: ORD200029 | B31: 45555 | C31: C33260 | D31: Desk | E31: 3 | F31: 423.53 | G31: 930 Main St | H31: Credit Card | I31: Delivered | J31: TRK59744090 | K31: 6 | L31: SAVE10 | M31: Referral | N31: 1270.59
A32: ORD200030 | B32: 45738 | C32: C44267 | D32: Monitor | E32: 2 | F32: 426.7 | G32: 895 Main St | H32: Online | I32: Pending | J32: TRK54751444 | K32: 5 | L32: SAVE10 | M32: Referral | N32: 853.4
A33: ORD200031 | B33: 45107 | C33: C26445 | D33: Chair | E33: 3 | F33: 500.08 | G33: 996 Main St | H33: Debit Card | I33: Returned | J33: TRK31229981 | K33: 6 | M33: Facebook | N33: 1500.24
A34: ORD200032 | B34: 45047 | C34: C12388 | D34: Tablet | E34: 5 | F34: 536.72 | G34: 830 Main St | H34: Cash | I34: Delivered | J34: TRK99261395 | K34: 10 | M34: Email | N34: 2683.6
A35: ORD200033 | B35: 45082 | C35: C52184 | D35: Chair | E35: 1 | F35: 162.77 | G35: 912 Main St | H35: Online | I35: Cancelled | J35: TRK73312471 | K35: 4 | L35: WINTER15 | M35: Facebook | N35: 162.77
A36: ORD200034 | B36: 44933 | C36: C67195 | D36: Chair | E36: 4 | F36: 576.52 | G36: 926 Main St | H36: Credit Card | I36: Pending | J36: TRK55467915 | K36: 5 | L36: WINTER15 | M36: Facebook | N36: 2306.08
A37: ORD200035 | B37: 45633 | C37: C50304 | D37: Monitor | E37: 2 | F37: 465.15 | G37: 128 Main St | H37: Online | I37: Shipped | J37: TRK46850888 | K37: 2 | L37: SAVE10 | M37: Facebook | N37: 930.3
A38: ORD200036 | B38: 45785 | C38: C59337 | D38: Laptop | E38: 2 | F38: 534.43 | G38: 465 Main St | H38: Debit Card | I38: Pending | J38: TRK50961250 | K38: 5 | M38: Facebook | N38: 1068.86
A39: ORD200037 | B39: 45579 | C39: C10054 | D39: Laptop | E39: 2 | F39: 76.74 | G39: 409 Main St | H39: Cash | I39: Returned | J39: TRK94005261 | K39: 7 | L39: SAVE10 | M39: Instagram | N39: 153.48
A40: ORD200038 | B40: 45645 | C40: C15924 | D40: Laptop | E40: 1 | F40: 245.89 | G40: 549 Main St | H40: Debit Card | I40: Delivered | J40: TRK14835975 | K40: 3 | L40: SAVE10 | M40: Google | N40: 245.89
...

Sheet Cleaned Data
A1: OrderID | B1: Date | C1: Year | D1: Month | E1: Quarter | F1: CustomerID | G1: Product | H1: Quantity | I1: UnitPrice | J1: ShippingAddress | K1: PaymentMethod | L1: OrderStatus | M1: TrackingNumber | N1: ItemsInCart | O1: CouponCode | P1: CouponCode2 | Q1: ReferralSource | R1: TotalPrice
A2: ORD200853 | B2: 45215 | C2: =YEAR(B2) -> 2023 | D2: =TEXT(B2,"mmmm") -> October | E2: ="Q"&ROUNDUP(MONTH(B2)/3,0) -> Q4 | F2: C10002 | G2: Printer | H2: 3 | I2: 490.01 | J2: 894 Main St | K2: Cash | L2: Returned | M2: TRK94641152 | N2: 4 | O2: SAVE10 | P2: =IF(ISBLANK(O2),"NO COUPON",O2) -> SAVE10 | Q2: Facebook | R2: 1470.03
A3: ORD200037 | B3: 45579 | C3: =YEAR(B3) -> 2024 | D3: =TEXT(B3,"mmmm") -> October | E3: ="Q"&ROUNDUP(MONTH(B3)/3,0) -> Q4 | F3: C10054 | G3: Laptop | H3: 2 | I3: 76.74 | J3: 409 Main St | K3: Cash | L3: Returned | M3: TRK94005261 | N3: 7 | O3: SAVE10 | P3: =IF(ISBLANK(O3),"NO COUPON",O3) -> SAVE10 | Q3: Instagram | R3: 153.48
A4: ORD200201 | B4: 45095 | C4: =YEAR(B4) -> 2023 | D4: =TEXT(B4,"mmmm") -> June | E4: ="Q"&ROUNDUP(MONTH(B4)/3,0) -> Q2 | F4: C10126 | G4: Monitor | H4: 2 | I4: 674.9 | J4: 146 Main St | K4: Online | L4: Shipped | M4: TRK75607531 | N4: 4 | O4: SAVE10 | P4: =IF(ISBLANK(O4),"NO COUPON",O4) -> SAVE10 | Q4: Facebook | R4: 1349.8
A5: ORD200728 | B5: 45502 | C5: =YEAR(B5) -> 2024 | D5: =TEXT(B5,"mmmm") -> July | E5: ="Q"&ROUNDUP(MONTH(B5)/3,0) -> Q3 | F5: C10154 | G5: Desk | H5: 4 | I5: 325.76 | J5: 827 Main St | K5: Gift Card | L5: Shipped | M5: TRK79793300 | N5: 8 | O5: WINTER15 | P5: =IF(ISBLANK(O5),"NO COUPON",O5) -> WINTER15 | Q5: Email | R5: 1303.04
A6: ORD200991 | B6: 45421 | C6: =YEAR(B6) -> 2024 | D6: =TEXT(B6,"mmmm") -> May | E6: ="Q"&ROUNDUP(MONTH(B6)/3,0) -> Q2 | F6: C10211 | G6: Desk | H6: 5 | I6: 127.18 | J6: 598 Main St | K6: Debit Card | L6: Cancelled | M6: TRK68938335 | N6: 10 | O6: FREESHIP | P6: =IF(ISBLANK(O6),"NO COUPON",O6) -> FREESHIP | Q6: Google | R6: 635.9
A7: ORD201184 | B7: 45196 | C7: =YEAR(B7) -> 2023 | D7: =TEXT(B7,"mmmm") -> September | E7: ="Q"&ROUNDUP(MONTH(B7)/3,0) -> Q3 | F7: C10222 | G7: Laptop | H7: 1 | I7: 204.08 | J7: 979 Main St | K7: Gift Card | L7: Returned | M7: TRK86297895 | N7: 4 | P7: =IF(ISBLANK(O7),"NO COUPON",O7) -> NO COUPON | Q7: Google | R7: 204.08
A8: ORD200667 | B8: 45049 | C8: =YEAR(B8) -> 2023 | D8: =TEXT(B8,"mmmm") -> May | E8: ="Q"&ROUNDUP(MONTH(B8)/3,0) -> Q2 | F8: C10477 | G8: Laptop | H8: 1 | I8: 466.42 | J8: 172 Main St | K8: Gift Card | L8: Pending | M8: TRK41505339 | N8: 5 | O8: SAVE10 | P8: =IF(ISBLANK(O8),"NO COUPON",O8) -> SAVE10 | Q8: Email | R8: 466.42
A9: ORD200744 | B9: 45455 | C9: =YEAR(B9) -> 2024 | D9: =TEXT(B9,"mmmm") -> June | E9: ="Q"&ROUNDUP(MONTH(B9)/3,0) -> Q2 | F9: C10642 | G9: Tablet | H9: 2 | I9: 461.37 | J9: 200 Main St | K9: Cash | L9: Delivered | M9: TRK98725693 | N9: 5 | O9: SAVE10 | P9: =IF(ISBLANK(O9),"NO COUPON",O9) -> SAVE10 | Q9: Google | R9: 922.74
A10: ORD201055 | B10: 45222 | C10: =YEAR(B10) -> 2023 | D10: =TEXT(B10,"mmmm") -> October | E10: ="Q"&ROUNDUP(MONTH(B10)/3,0) -> Q4 | F10: C10787 | G10: Monitor | H10: 4 | I10: 274.82 | J10: 932 Main St | K10: Debit Card | L10: Delivered | M10: TRK91512567 | N10: 9 | O10: WINTER15 | P10: =IF(ISBLANK(O10),"NO COUPON",O10) -> WINTER15 | Q10: Email | R10: 1099.28
A11: ORD201066 | B11: 45280 | C11: =YEAR(B11) -> 2023 | D11: =TEXT(B11,"mmmm") -> December | E11: ="Q"&ROUNDUP(MONTH(B11)/3,0) -> Q4 | F11: C10791 | G11: Desk | H11: 1 | I11: 355.09 | J11: 674 Main St | K11: Debit Card | L11: Cancelled | M11: TRK20321248 | N11: 5 | O11: SAVE10 | P11: =IF(ISBLANK(O11),"NO COUPON",O11) -> SAVE10 | Q11: Instagram | R11: 355.09
A12: ORD200254 | B12: 45286 | C12: =YEAR(B12) -> 2023 | D12: =TEXT(B12,"mmmm") -> December | E12: ="Q"&ROUNDUP(MONTH(B12)/3,0) -> Q4 | F12: C10866 | G12: Monitor | H12: 3 | I12: 263.19 | J12: 770 Main St | K12: Online | L12: Delivered | M12: TRK34809583 | N12: 5 | P12: =IF(ISBLANK(O12),"NO COUPON",O12) -> NO COUPON | Q12: Instagram | R12: 789.57
A13: ORD200740 | B13: 45493 | C13: =YEAR(B13) -> 2024 | D13: =TEXT(B13,"mmmm") -> July | E13: ="Q"&ROUNDUP(MONTH(B13)/3,0) -> Q3 | F13: C10892 | G13: Desk | H13: 2 | I13: 377.47 | J13: 433 Main St | K13: Cash | L13: Pending | M13: TRK76154554 | N13: 7 | P13: =IF(ISBLANK(O13),"NO COUPON",O13) -> NO COUPON | Q13: Google | R13: 754.94
A14: ORD200859 | B14: 45532 | C14: =YEAR(B14) -> 2024 | D14: =TEXT(B14,"mmmm") -> August | E14: ="Q"&ROUNDUP(MONTH(B14)/3,0) -> Q3 | F14: C11127 | G14: Chair | H14: 5 | I14: 261.33 | J14: 154 Main St | K14: Credit Card | L14: Returned | M14: TRK73285507 | N14: 5 | O14: SAVE10 | P14: =IF(ISBLANK(O14),"NO COUPON",O14) -> SAVE10 | Q14: Referral | R14: 1306.65
A15: ORD200277 | B15: 45544 | C15: =YEAR(B15) -> 2024 | D15: =TEXT(B15,"mmmm") -> September | E15: ="Q"&ROUNDUP(MONTH(B15)/3,0) -> Q3 | F15: C11210 | G15: Chair | H15: 5 | I15: 90.92 | J15: 910 Main St | K15: Credit Card | L15: Delivered | M15: TRK44929965 | N15: 9 | O15: SAVE10 | P15: =IF(ISBLANK(O15),"NO COUPON",O15) -> SAVE10 | Q15: Facebook | R15: 454.6
A16: ORD200511 | B16: 45366 | C16: =YEAR(B16) -> 2024 | D16: =TEXT(B16,"mmmm") -> March | E16: ="Q"&ROUNDUP(MONTH(B16)/3,0) -> Q1 | F16: C11415 | G16: Monitor | H16: 5 | I16: 575.24 | J16: 267 Main St | K16: Cash | L16: Delivered | M16: TRK65061457 | N16: 7 | O16: WINTER15 | P16: =IF(ISBLANK(O16),"NO COUPON",O16) -> WINTER15 | Q16: Email | R16: 2876.2
A17: ORD201135 | B17: 45288 | C17: =YEAR(B17) -> 2023 | D17: =TEXT(B17,"mmmm") -> December | E17: ="Q"&ROUNDUP(MONTH(B17)/3,0) -> Q4 | F17: C11473 | G17: Printer | H17: 2 | I17: 73.41 | J17: 562 Main St | K17: Online | L17: Shipped | M17: TRK97793275 | N17: 2 | O17: SAVE10 | P17: =IF(ISBLANK(O17),"NO COUPON",O17) -> SAVE10 | Q17: Google | R17: 146.82
A18: ORD200193 | B18: 45128 | C18: =YEAR(B18) -> 2023 | D18: =TEXT(B18,"mmmm") -> July | E18: ="Q"&ROUNDUP(MONTH(B18)/3,0) -> Q3 | F18: C11644 | G18: Printer | H18: 1 | I18: 46.66 | J18: 429 Main St | K18: Cash | L18: Cancelled | M18: TRK81320339 | N18: 6 | P18: =IF(ISBLANK(O18),"NO COUPON",O18) -> NO COUPON | Q18: Google | R18: 46.66
A19: ORD200406 | B19: 45270 | C19: =YEAR(B19) -> 2023 | D19: =TEXT(B19,"mmmm") -> December | E19: ="Q"&ROUNDUP(MONTH(B19)/3,0) -> Q4 | F19: C11657 | G19: Tablet | H19: 4 | I19: 66.1 | J19: 572 Main St | K19: Cash | L19: Returned | M19: TRK50284486 | N19: 9 | O19: WINTER15 | P19: =IF(ISBLANK(O19),"NO COUPON",O19) -> WINTER15 | Q19: Google | R19: 264.4
A20: ORD200218 | B20: 45044 | C20: =YEAR(B20) -> 2023 | D20: =TEXT(B20,"mmmm") -> April | E20: ="Q"&ROUNDUP(MONTH(B20)/3,0) -> Q2 | F20: C11665 | G20: Tablet | H20: 3 | I20: 112.46 | J20: 882 Main St | K20: Gift Card | L20: Shipped | M20: TRK10993930 | N20: 6 | O20: SAVE10 | P20: =IF(ISBLANK(O20),"NO COUPON",O20) -> SAVE10 | Q20: Instagram | R20: 337.38
A21: ORD200504 | B21: 45819 | C21: =YEAR(B21) -> 2025 | D21: =TEXT(B21,"mmmm") -> June | E21: ="Q"&ROUNDUP(MONTH(B21)/3,0) -> Q2 | F21: C11676 | G21: Monitor | H21: 2 | I21: 464.5 | J21: 805 Main St | K21: Online | L21: Cancelled | M21: TRK35726395 | N21: 2 | O21: WINTER15 | P21: =IF(ISBLANK(O21),"NO COUPON",O21) -> WINTER15 | Q21: Instagram | R21: 929
A22: ORD200414 | B22: 45781 | C22: =YEAR(B22) -> 2025 | D22: =TEXT(B22,"mmmm") -> May | E22: ="Q"&ROUNDUP(MONTH(B22)/3,0) -> Q2 | F22: C11829 | G22: Desk | H22: 2 | I22: 139.57 | J22: 797 Main St | K22: Cash | L22: Delivered | M22: TRK84229257 | N22: 4 | O22: WINTER15 | P22: =IF(ISBLANK(O22),"NO COUPON",O22) -> WINTER15 | Q22: Facebook | R22: 279.14
A23: ORD200273 | B23: 45592 | C23: =YEAR(B23) -> 2024 | D23: =TEXT(B23,"mmmm") -> October | E23: ="Q"&ROUNDUP(MONTH(B23)/3,0) -> Q4 | F23: C11849 | G23: Tablet | H23: 2 | I23: 238.25 | J23: 974 Main St | K23: Online | L23: Cancelled | M23: TRK91195261 | N23: 7 | O23: FREESHIP | P23: =IF(ISBLANK(O23),"NO COUPON",O23) -> FREESHIP | Q23: Email | R23: 476.5
A24: ORD201045 | B24: 45555 | C24: =YEAR(B24) -> 2024 | D24: =TEXT(B24,"mmmm") -> September | E24: ="Q"&ROUNDUP(MONTH(B24)/3,0) -> Q3 | F24: C11893 | G24: Laptop | H24: 5 | I24: 316.4 | J24: 671 Main St | K24: Gift Card | L24: Returned | M24: TRK72012758 | N24: 7 | P24: =IF(ISBLANK(O24),"NO COUPON",O24) -> NO COUPON | Q24: Email | R24: 1582
A25: ORD200408 | B25: 45658 | C25: =YEAR(B25) -> 2025 | D25: =TEXT(B25,"mmmm") -> January | E25: ="Q"&ROUNDUP(MONTH(B25)/3,0) -> Q1 | F25: C11906 | G25: Printer | H25: 3 | I25: 412.53 | J25: 536 Main St | K25: Online | L25: Pending | M25: TRK31140158 | N25: 6 | O25: WINTER15 | P25: =IF(ISBLANK(O25),"NO COUPON",O25) -> WINTER15 | Q25: Google | R25: 1237.59
A26: ORD200420 | B26: 45625 | C26: =YEAR(B26) -> 2024 | D26: =TEXT(B26,"mmmm") -> November | E26: ="Q"&ROUNDUP(MONTH(B26)/3,0) -> Q4 | F26: C11921 | G26: Phone | H26: 1 | I26: 452.7 | J26: 439 Main St | K26: Debit Card | L26: Shipped | M26: TRK91362635 | N26: 5 | O26: FREESHIP | P26: =IF(ISBLANK(O26),"NO COUPON",O26) -> FREESHIP | Q26: Instagram | R26: 452.7
A27: ORD200489 | B27: 45174 | C27: =YEAR(B27) -> 2023 | D27: =TEXT(B27,"mmmm") -> September | E27: ="Q"&ROUNDUP(MONTH(B27)/3,0) -> Q3 | F27: C11940 | G27: Tablet | H27: 3 | I27: 149.34 | J27: 589 Main St | K27: Gift Card | L27: Cancelled | M27: TRK85466461 | N27: 7 | O27: WINTER15 | P27: =IF(ISBLANK(O27),"NO COUPON",O27) -> WINTER15 | Q27: Email | R27: 448.02
A28: ORD200049 | B28: 45206 | C28: =YEAR(B28) -> 2023 | D28: =TEXT(B28,"mmmm") -> October | E28: ="Q"&ROUNDUP(MONTH(B28)/3,0) -> Q4 | F28: C11985 | G28: Printer | H28: 1 | I28: 30.44 | J28: 633 Main St | K28: Credit Card | L28: Shipped | M28: TRK53272402 | N28: 1 | O28: SAVE10 | P28: =IF(ISBLANK(O28),"NO COUPON",O28) -> SAVE10 | Q28: Email | R28: 30.44
A29: ORD201141 | B29: 45704 | C29: =YEAR(B29) -> 2025 | D29: =TEXT(B29,"mmmm") -> February | E29: ="Q"&ROUNDUP(MONTH(B29)/3,0) -> Q1 | F29: C11998 | G29: Chair | H29: 3 | I29: 498.66 | J29: 382 Main St | K29: Cash | L29: Cancelled | M29: TRK26707221 | N29: 6 | P29: =IF(ISBLANK(O29),"NO COUPON",O29) -> NO COUPON | Q29: Email | R29: 1495.98
A30: ORD200563 | B30: 45272 | C30: =YEAR(B30) -> 2023 | D30: =TEXT(B30,"mmmm") -> December | E30: ="Q"&ROUNDUP(MONTH(B30)/3,0) -> Q4 | F30: C12039 | G30: Laptop | H30: 1 | I30: 132.68 | J30: 844 Main St | K30: Debit Card | L30: Returned | M30: TRK68645763 | N30: 1 | O30: SAVE10 | P30: =IF(ISBLANK(O30),"NO COUPON",O30) -> SAVE10 | Q30: Referral | R30: 132.68
A31: ORD200260 | B31: 45063 | C31: =YEAR(B31) -> 2023 | D31: =TEXT(B31,"mmmm") -> May | E31: ="Q"&ROUNDUP(MONTH(B31)/3,0) -> Q2 | F31: C12245 | G31: Monitor | H31: 2 | I31: 407.79 | J31: 153 Main St | K31: Debit Card | L31: Shipped | M31: TRK22000463 | N31: 3 | P31: =IF(ISBLANK(O31),"NO COUPON",O31) -> NO COUPON | Q31: Google | R31: 815.58
A32: ORD201052 | B32: 45180 | C32: =YEAR(B32) -> 2023 | D32: =TEXT(B32,"mmmm") -> September | E32: ="Q"&ROUNDUP(MONTH(B32)/3,0) -> Q3 | F32: C12301 | G32: Tablet | H32: 1 | I32: 531.74 | J32: 493 Main St | K32: Online | L32: Shipped | M32: TRK25145796 | N32: 1 | O32: WINTER15 | P32: =IF(ISBLANK(O32),"NO COUPON",O32) -> WINTER15 | Q32: Google | R32: 531.74
A33: ORD200032 | B33: 45047 | C33: =YEAR(B33) -> 2023 | D33: =TEXT(B33,"mmmm") -> May | E33: ="Q"&ROUNDUP(MONTH(B33)/3,0) -> Q2 | F33: C12388 | G33: Tablet | H33: 5 | I33: 536.72 | J33: 830 Main St | K33: Cash | L33: Delivered | M33: TRK99261395 | N33: 10 | P33: =IF(ISBLANK(O33),"NO COUPON",O33) -> NO COUPON | Q33: Email | R33: 2683.6
A34: ORD200048 | B34: 45164 | C34: =YEAR(B34) -> 2023 | D34: =TEXT(B34,"mmmm") -> August | E34: ="Q"&ROUNDUP(MONTH(B34)/3,0) -> Q3 | F34: C12408 | G34: Monitor | H34: 2 | I34: 80.77 | J34: 464 Main St | K34: Debit Card | L34: Shipped | M34: TRK38938858 | N34: 4 | P34: =IF(ISBLANK(O34),"NO COUPON",O34) -> NO COUPON | Q34: Google | R34: 161.54
A35: ORD200386 | B35: 45044 | C35: =YEAR(B35) -> 2023 | D35: =TEXT(B35,"mmmm") -> April | E35: ="Q"&ROUNDUP(MONTH(B35)/3,0) -> Q2 | F35: C12421 | G35: Tablet | H35: 1 | I35: 93.02 | J35: 373 Main St | K35: Online | L35: Returned | M35: TRK32588504 | N35: 4 | P35: =IF(ISBLANK(O35),"NO COUPON",O35) -> NO COUPON | Q35: Email | R35: 93.02
A36: ORD200762 | B36: 45552 | C36: =YEAR(B36) -> 2024 | D36: =TEXT(B36,"mmmm") -> September | E36: ="Q"&ROUNDUP(MONTH(B36)/3,0) -> Q3 | F36: C12444 | G36: Phone | H36: 3 | I36: 76.96 | J36: 611 Main St | K36: Cash | L36: Returned | M36: TRK97621403 | N36: 8 | O36: FREESHIP | P36: =IF(ISBLANK(O36),"NO COUPON",O36) -> FREESHIP | Q36: Email | R36: 230.88
A37: ORD200962 | B37: 45541 | C37: =YEAR(B37) -> 2024 | D37: =TEXT(B37,"mmmm") -> September | E37: ="Q"&ROUNDUP(MONTH(B37)/3,0) -> Q3 | F37: C12459 | G37: Phone | H37: 2 | I37: 142.08 | J37: 838 Main St | K37: Gift Card | L37: Delivered | M37: TRK30674085 | N37: 4 | O37: SAVE10 | P37: =IF(ISBLANK(O37),"NO COUPON",O37) -> SAVE10 | Q37: Referral | R37: 284.16
A38: ORD201110 | B38: 45347 | C38: =YEAR(B38) -> 2024 | D38: =TEXT(B38,"mmmm") -> February | E38: ="Q"&ROUNDUP(MONTH(B38)/3,0) -> Q1 | F38: C12472 | G38: Chair | H38: 3 | I38: 84.31 | J38: 912 Main St | K38: Credit Card | L38: Shipped | M38: TRK36103184 | N38: 3 | O38: SAVE10 | P38: =IF(ISBLANK(O38),"NO COUPON",O38) -> SAVE10 | Q38: Email | R38: 252.93
A39: ORD200601 | B39: 45201 | C39: =YEAR(B39) -> 2023 | D39: =TEXT(B39,"mmmm") -> October | E39: ="Q"&ROUNDUP(MONTH(B39)/3,0) -> Q4 | F39: C12479 | G39: Monitor | H39: 5 | I39: 24.82 | J39: 529 Main St | K39: Credit Card | L39: Shipped | M39: TRK73935314 | N39: 10 | P39: =IF(ISBLANK(O39),"NO COUPON",O39) -> NO COUPON | Q39: Referral | R39: 124.1
A40: ORD201105 | B40: 45299 | C40: =YEAR(B40) -> 2024 | D40: =TEXT(B40,"mmmm") -> January | E40: ="Q"&ROUNDUP(MONTH(B40)/3,0) -> Q1 | F40: C12487 | G40: Tablet | H40: 3 | I40: 475.69 | J40: 884 Main St | K40: Gift Card | L40: Cancelled | M40: TRK23324770 | N40: 3 | O40: FREESHIP | P40: =IF(ISBLANK(O40),"NO COUPON",O40) -> FREESHIP | Q40: Google | R40: 1427.07
...

Sheet Z-Score Outliers
A1: OrderID | B1: Date | C1: Year | D1: Month | E1: Quarter | F1: CustomerID | G1: Product | H1: Quantity | I1: UnitPrice | J1: ShippingAddress | K1: PaymentMethod | L1: OrderStatus | M1: TrackingNumber | N1: ItemsInCart | O1: CouponCode | P1: CouponCode2 | Q1: ReferralSource | R1: TotalPrice | S1: ProductAverage | T1: SD of product | U1: Z-Score | V1: Outliers?
A2: ORD200853 | B2: 45215 | C2: =YEAR(B2) -> 2023 | D2: =TEXT(B2,"mmmm") -> October | E2: ="Q"&ROUNDUP(MONTH(B2)/3,0) -> Q4 | F2: C10002 | G2: Printer | H2: 3 | I2: 490.01 | J2: 894 Main St | K2: Cash | L2: Returned | M2: TRK94641152 | N2: 4 | O2: SAVE10 | P2: =IF(ISBLANK(O2),"NO COUPON",O2) -> SAVE10 | Q2: Facebook | R2: 1470.03 | S2: =AVERAGEIF($G$2:$G$1201,G2,$R$2:$R$1201) -> 1080.7327 | T2: {=_xlfn.STDEV.P(_xlfn._xlws.FILTER($R$2:$R$1201,$G$2:$G$1201=G2))} -> 851.72194 | U2: =ABS(I2-S2)/T2 -> 0.6935628 | V2: =IF(U2>3,"Yes","No") -> No
A3: ORD200037 | B3: 45579 | C3: =YEAR(B3) -> 2024 | D3: =TEXT(B3,"mmmm") -> October | E3: ="Q"&ROUNDUP(MONTH(B3)/3,0) -> Q4 | F3: C10054 | G3: Laptop | H3: 2 | I3: 76.74 | J3: 409 Main St | K3: Cash | L3: Returned | M3: TRK94005261 | N3: 7 | O3: SAVE10 | P3: =IF(ISBLANK(O3),"NO COUPON",O3) -> SAVE10 | Q3: Instagram | R3: 153.48 | S3: =AVERAGEIF($G$2:$G$1201,G3,$R$2:$R$1201) -> 1110.5582 | T3: {=_xlfn.STDEV.P(_xlfn._xlws.FILTER($R$2:$R$1201,$G$2:$G$1201=G3))} -> 859.60878 | U3: =ABS(I3-S3)/T3 -> 1.2026612 | V3: =IF(U3>3,"Yes","No") -> No
A4: ORD200201 | B4: 45095 | C4: =YEAR(B4) -> 2023 | D4: =TEXT(B4,"mmmm") -> June | E4: ="Q"&ROUNDUP(MONTH(B4)/3,0) -> Q2 | F4: C10126 | G4: Monitor | H4: 2 | I4: 674.9 | J4: 146 Main St | K4: Online | L4: Shipped | M4: TRK75607531 | N4: 4 | O4: SAVE10 | P4: =IF(ISBLANK(O4),"NO COUPON",O4) -> SAVE10 | Q4: Facebook | R4: 1349.8 | S4: =AVERAGEIF($G$2:$G$1201,G4,$R$2:$R$1201) -> 1077.616 | T4: {=_xlfn.STDEV.P(_xlfn._xlws.FILTER($R$2:$R$1201,$G$2:$G$1201=G4))} -> 847.57365 | U4: =ABS(I4-S4)/T4 -> 0.47513985 | V4: =IF(U4>3,"Yes","No") -> No
A5: ORD200728 | B5: 45502 | C5: =YEAR(B5) -> 2024 | D5: =TEXT(B5,"mmmm") -> July | E5: ="Q"&ROUNDUP(MONTH(B5)/3,0) -> Q3 | F5: C10154 | G5: Desk | H5: 4 | I5: 325.76 | J5: 827 Main St | K5: Gift Card | L5: Shipped | M5: TRK79793300 | N5: 8 | O5: WINTER15 | P5: =IF(ISBLANK(O5),"NO COUPON",O5) -> WINTER15 | Q5: Email | R5: 1303.04 | S5: =AVERAGEIF($G$2:$G$1201,G5,$R$2:$R$1201) -> 985.05841 | T5: {=_xlfn.STDEV.P(_xlfn._xlws.FILTER($R$2:$R$1201,$G$2:$G$1201=G5))} -> 745.08439 | U5: =ABS(I5-S5)/T5 -> 0.88486407 | V5: =IF(U5>3,"Yes","No") -> No
A6: ORD200991 | B6: 45421 | C6: =YEAR(B6) -> 2024 | D6: =TEXT(B6,"mmmm") -> May | E6: ="Q"&ROUNDUP(MONTH(B6)/3,0) -> Q2 | F6: C10211 | G6: Desk | H6: 5 | I6: 127.18 | J6: 598 Main St | K6: Debit Card | L6: Cancelled | M6: TRK68938335 | N6: 10 | O6: FREESHIP | P6: =IF(ISBLANK(O6),"NO COUPON",O6) -> FREESHIP | Q6: Google | R6: 635.9 | S6: =AVERAGEIF($G$2:$G$1201,G6,$R$2:$R$1201) -> 985.05841 | T6: {=_xlfn.STDEV.P(_xlfn._xlws.FILTER($R$2:$R$1201,$G$2:$G$1201=G6))} -> 745.08439 | U6: =ABS(I6-S6)/T6 -> 1.1513842 | V6: =IF(U6>3,"Yes","No") -> No
A7: ORD201184 | B7: 45196 | C7: =YEAR(B7) -> 2023 | D7: =TEXT(B7,"mmmm") -> September | E7: ="Q"&ROUNDUP(MONTH(B7)/3,0) -> Q3 | F7: C10222 | G7: Laptop | H7: 1 | I7: 204.08 | J7: 979 Main St | K7: Gift Card | L7: Returned | M7: TRK86297895 | N7: 4 | P7: =IF(ISBLANK(O7),"NO COUPON",O7) -> NO COUPON | Q7: Google | R7: 204.08 | S7: =AVERAGEIF($G$2:$G$1201,G7,$R$2:$R$1201) -> 1110.5582 | T7: {=_xlfn.STDEV.P(_xlfn._xlws.FILTER($R$2:$R$1201,$G$2:$G$1201=G7))} -> 859.60878 | U7: =ABS(I7-S7)/T7 -> 1.0545241 | V7: =IF(U7>3,"Yes","No") -> No
A8: ORD200667 | B8: 45049 | C8: =YEAR(B8) -> 2023 | D8: =TEXT(B8,"mmmm") -> May | E8: ="Q"&ROUNDUP(MONTH(B8)/3,0) -> Q2 | F8: C10477 | G8: Laptop | H8: 1 | I8: 466.42 | J8: 172 Main St | K8: Gift Card | L8: Pending | M8: TRK41505339 | N8: 5 | O8: SAVE10 | P8: =IF(ISBLANK(O8),"NO COUPON",O8) -> SAVE10 | Q8: Email | R8: 466.42 | S8: =AVERAGEIF($G$2:$G$1201,G8,$R$2:$R$1201) -> 1110.5582 | T8: {=_xlfn.STDEV.P(_xlfn._xlws.FILTER($R$2:$R$1201,$G$2:$G$1201=G8))} -> 859.60878 | U8: =ABS(I8-S8)/T8 -> 0.74933873 | V8: =IF(U8>3,"Yes","No") -> No
A9: ORD200744 | B9: 45455 | C9: =YEAR(B9) -> 2024 | D9: =TEXT(B9,"mmmm") -> June | E9: ="Q"&ROUNDUP(MONTH(B9)/3,0) -> Q2 | F9: C10642 | G9: Tablet | H9: 2 | I9: 461.37 | J9: 200 Main St | K9: Cash | L9: Delivered | M9: TRK98725693 | N9: 5 | O9: SAVE10 | P9: =IF(ISBLANK(O9),"NO COUPON",O9) -> SAVE10 | Q9: Google | R9: 922.74 | S9: =AVERAGEIF($G$2:$G$1201,G9,$R$2:$R$1201) -> 1042.2846 | T9: {=_xlfn.STDEV.P(_xlfn._xlws.FILTER($R$2:$R$1201,$G$2:$G$1201=G9))} -> 832.06806 | U9: =ABS(I9-S9)/T9 -> 0.6981576 | V9: =IF(U9>3,"Yes","No") -> No
A10: ORD201055 | B10: 45222 | C10: =YEAR(B10) -> 2023 | D10: =TEXT(B10,"mmmm") -> October | E10: ="Q"&ROUNDUP(MONTH(B10)/3,0) -> Q4 | F10: C10787 | G10: Monitor | H10: 4 | I10: 274.82 | J10: 932 Main St | K10: Debit Card | L10: Delivered | M10: TRK91512567 | N10: 9 | O10: WINTER15 | P10: =IF(ISBLANK(O10),"NO COUPON",O10) -> WINTER15 | Q10: Email | R10: 1099.28 | S10: =AVERAGEIF($G$2:$G$1201,G10,$R$2:$R$1201) -> 1077.616 | T10: {=_xlfn.STDEV.P(_xlfn._xlws.FILTER($R$2:$R$1201,$G$2:$G$1201=G10))} -> 847.57365 | U10: =ABS(I10-S10)/T10 -> 0.94716962 | V10: =IF(U10>3,"Yes","No") -> No
A11: ORD201066 | B11: 45280 | C11: =YEAR(B11) -> 2023 | D11: =TEXT(B11,"mmmm") -> December | E11: ="Q"&ROUNDUP(MONTH(B11)/3,0) -> Q4 | F11: C10791 | G11: Desk | H11: 1 | I11: 355.09 | J11: 674 Main St | K11: Debit Card | L11: Cancelled | M11: TRK20321248 | N11: 5 | O11: SAVE10 | P11: =IF(ISBLANK(O11),"NO COUPON",O11) -> SAVE10 | Q11: Instagram | R11: 355.09 | S11: =AVERAGEIF($G$2:$G$1201,G11,$R$2:$R$1201) -> 985.05841 | T11: {=_xlfn.STDEV.P(_xlfn._xlws.FILTER($R$2:$R$1201,$G$2:$G$1201=G11))} -> 745.08439 | U11: =ABS(I11-S11)/T11 -> 0.84549941 | V11: =IF(U11>3,"Yes","No") -> No
A12: ORD200254 | B12: 45286 | C12: =YEAR(B12) -> 2023 | D12: =TEXT(B12,"mmmm") -> December | E12: ="Q"&ROUNDUP(MONTH(B12)/3,0) -> Q4 | F12: C10866 | G12: Monitor | H12: 3 | I12: 263.19 | J12: 770 Main St | K12: Online | L12: Delivered | M12: TRK34809583 | N12: 5 | P12: =IF(ISBLANK(O12),"NO COUPON",O12) -> NO COUPON | Q12: Instagram | R12: 789.57 | S12: =AVERAGEIF($G$2:$G$1201,G12,$R$2:$R$1201) -> 1077.616 | T12: {=_xlfn.STDEV.P(_xlfn._xlws.FILTER($R$2:$R$1201,$G$2:$G$1201=G12))} -> 847.57365 | U12: =ABS(I12-S12)/T12 -> 0.96089115 | V12: =IF(U12>3,"Yes","No") -> No
A13: ORD200740 | B13: 45493 | C13: =YEAR(B13) -> 2024 | D13: =TEXT(B13,"mmmm") -> July | E13: ="Q"&ROUNDUP(MONTH(B13)/3,0) -> Q3 | F13: C10892 | G13: Desk | H13: 2 | I13: 377.47 | J13: 433 Main St | K13: Cash | L13: Pending | M13: TRK76154554 | N13: 7 | P13: =IF(ISBLANK(O13),"NO COUPON",O13) -> NO COUPON | Q13: Google | R13: 754.94 | S13: =AVERAGEIF($G$2:$G$1201,G13,$R$2:$R$1201) -> 985.05841 | T13: {=_xlfn.STDEV.P(_xlfn._xlws.FILTER($R$2:$R$1201,$G$2:$G$1201=G13))} -> 745.08439 | U13: =ABS(I13-S13)/T13 -> 0.81546254 | V13: =IF(U13>3,"Yes","No") -> No
A14: ORD200859 | B14: 45532 | C14: =YEAR(B14) -> 2024 | D14: =TEXT(B14,"mmmm") -> August | E14: ="Q"&ROUNDUP(MONTH(B14)/3,0) -> Q3 | F14: C11127 | G14: Chair | H14: 5 | I14: 261.33 | J14: 154 Main St | K14: Credit Card | L14: Returned | M14: TRK73285507 | N14: 5 | O14: SAVE10 | P14: =IF(ISBLANK(O14),"NO COUPON",O14) -> SAVE10 | Q14: Referral | R14: 1306.65 | S14: =AVERAGEIF($G$2:$G$1201,G14,$R$2:$R$1201) -> 1098.9894 | T14: {=_xlfn.STDEV.P(_xlfn._xlws.FILTER($R$2:$R$1201,$G$2:$G$1201=G14))} -> 817.71888 | U14: =ABS(I14-S14)/T14 -> 1.0243855 | V14: =IF(U14>3,"Yes","No") -> No
A15: ORD200277 | B15: 45544 | C15: =YEAR(B15) -> 2024 | D15: =TEXT(B15,"mmmm") -> September | E15: ="Q"&ROUNDUP(MONTH(B15)/3,0) -> Q3 | F15: C11210 | G15: Chair | H15: 5 | I15: 90.92 | J15: 910 Main St | K15: Credit Card | L15: Delivered | M15: TRK44929965 | N15: 9 | O15: SAVE10 | P15: =IF(ISBLANK(O15),"NO COUPON",O15) -> SAVE10 | Q15: Facebook | R15: 454.6 | S15: =AVERAGEIF($G$2:$G$1201,G15,$R$2:$R$1201) -> 1098.9894 | T15: {=_xlfn.STDEV.P(_xlfn._xlws.FILTER($R$2:$R$1201,$G$2:$G$1201=G15))} -> 817.71888 | U15: =ABS(I15-S15)/T15 -> 1.2327823 | V15: =IF(U15>3,"Yes","No") -> No
A16: ORD200511 | B16: 45366 | C16: =YEAR(B16) -> 2024 | D16: =TEXT(B16,"mmmm") -> March | E16: ="Q"&ROUNDUP(MONTH(B16)/3,0) -> Q1 | F16: C11415 | G16: Monitor | H16: 5 | I16: 575.24 | J16: 267 Main St | K16: Cash | L16: Delivered | M16: TRK65061457 | N16: 7 | O16: WINTER15 | P16: =IF(ISBLANK(O16),"NO COUPON",O16) -> WINTER15 | Q16: Email | R16: 2876.2 | S16: =AVERAGEIF($G$2:$G$1201,G16,$R$2:$R$1201) -> 1077.616 | T16: {=_xlfn.STDEV.P(_xlfn._xlws.FILTER($R$2:$R$1201,$G$2:$G$1201=G16))} -> 847.57365 | U16: =ABS(I16-S16)/T16 -> 0.59272255 | V16: =IF(U16>3,"Yes","No") -> No
A17: ORD201135 | B17: 45288 | C17: =YEAR(B17) -> 2023 | D17: =TEXT(B17,"mmmm") -> December | E17: ="Q"&ROUNDUP(MONTH(B17)/3,0) -> Q4 | F17: C11473 | G17: Printer | H17: 2 | I17: 73.41 | J17: 562 Main St | K17: Online | L17: Shipped | M17: TRK97793275 | N17: 2 | O17: SAVE10 | P17: =IF(ISBLANK(O17),"NO COUPON",O17) -> SAVE10 | Q17: Google | R17: 146.82 | S17: =AVERAGEIF($G$2:$G$1201,G17,$R$2:$R$1201) -> 1080.7327 | T17: {=_xlfn.STDEV.P(_xlfn._xlws.FILTER($R$2:$R$1201,$G$2:$G$1201=G17))} -> 851.72194 | U17: =ABS(I17-S17)/T17 -> 1.1826896 | V17: =IF(U17>3,"Yes","No") -> No
A18: ORD200193 | B18: 45128 | C18: =YEAR(B18) -> 2023 | D18: =TEXT(B18,"mmmm") -> July | E18: ="Q"&ROUNDUP(MONTH(B18)/3,0) -> Q3 | F18: C11644 | G18: Printer | H18: 1 | I18: 46.66 | J18: 429 Main St | K18: Cash | L18: Cancelled | M18: TRK81320339 | N18: 6 | P18: =IF(ISBLANK(O18),"NO COUPON",O18) -> NO COUPON | Q18: Google | R18: 46.66 | S18: =AVERAGEIF($G$2:$G$1201,G18,$R$2:$R$1201) -> 1080.7327 | T18: {=_xlfn.STDEV.P(_xlfn._xlws.FILTER($R$2:$R$1201,$G$2:$G$1201=G18))} -> 851.72194 | U18: =ABS(I18-S18)/T18 -> 1.2140965 | V18: =IF(U18>3,"Yes","No") -> No
A19: ORD200406 | B19: 45270 | C19: =YEAR(B19) -> 2023 | D19: =TEXT(B19,"mmmm") -> December | E19: ="Q"&ROUNDUP(MONTH(B19)/3,0) -> Q4 | F19: C11657 | G19: Tablet | H19: 4 | I19: 66.1 | J19: 572 Main St | K19: Cash | L19: Returned | M19: TRK50284486 | N19: 9 | O19: WINTER15 | P19: =IF(ISBLANK(O19),"NO COUPON",O19) -> WINTER15 | Q19: Google | R19: 264.4 | S19: =AVERAGEIF($G$2:$G$1201,G19,$R$2:$R$1201) -> 1042.2846 | T19: {=_xlfn.STDEV.P(_xlfn._xlws.FILTER($R$2:$R$1201,$G$2:$G$1201=G19))} -> 832.06806 | U19: =ABS(I19-S19)/T19 -> 1.1732029 | V19: =IF(U19>3,"Yes","No") -> No
A20: ORD200218 | B20: 45044 | C20: =YEAR(B20) -> 2023 | D20: =TEXT(B20,"mmmm") -> April | E20: ="Q"&ROUNDUP(MONTH(B20)/3,0) -> Q2 | F20: C11665 | G20: Tablet | H20: 3 | I20: 112.46 | J20: 882 Main St | K20: Gift Card | L20: Shipped | M20: TRK10993930 | N20: 6 | O20: SAVE10 | P20: =IF(ISBLANK(O20),"NO COUPON",O20) -> SAVE10 | Q20: Instagram | R20: 337.38 | S20: =AVERAGEIF($G$2:$G$1201,G20,$R$2:$R$1201) -> 1042.2846 | T20: {=_xlfn.STDEV.P(_xlfn._xlws.FILTER($R$2:$R$1201,$G$2:$G$1201=G20))} -> 832.06806 | U20: =ABS(I20-S20)/T20 -> 1.1174863 | V20: =IF(U20>3,"Yes","No") -> No
A21: ORD200504 | B21: 45819 | C21: =YEAR(B21) -> 2025 | D21: =TEXT(B21,"mmmm") -> June | E21: ="Q"&ROUNDUP(MONTH(B21)/3,0) -> Q2 | F21: C11676 | G21: Monitor | H21: 2 | I21: 464.5 | J21: 805 Main St | K21: Online | L21: Cancelled | M21: TRK35726395 | N21: 2 | O21: WINTER15 | P21: =IF(ISBLANK(O21),"NO COUPON",O21) -> WINTER15 | Q21: Instagram | R21: 929 | S21: =AVERAGEIF($G$2:$G$1201,G21,$R$2:$R$1201) -> 1077.616 | T21: {=_xlfn.STDEV.P(_xlfn._xlws.FILTER($R$2:$R$1201,$G$2:$G$1201=G21))} -> 847.57365 | U21: =ABS(I21-S21)/T21 -> 0.72337786 | V21: =IF(U21>3,"Yes","No") -> No
A22: ORD200414 | B22: 45781 | C22: =YEAR(B22) -> 2025 | D22: =TEXT(B22,"mmmm") -> May | E22: ="Q"&ROUNDUP(MONTH(B22)/3,0) -> Q2 | F22: C11829 | G22: Desk | H22: 2 | I22: 139.57 | J22: 797 Main St | K22: Cash | L22: Delivered | M22: TRK84229257 | N22: 4 | O22: WINTER15 | P22: =IF(ISBLANK(O22),"NO COUPON",O22) -> WINTER15 | Q22: Facebook | R22: 279.14 | S22: =AVERAGEIF($G$2:$G$1201,G22,$R$2:$R$1201) -> 985.05841 | T22: {=_xlfn.STDEV.P(_xlfn._xlws.FILTER($R$2:$R$1201,$G$2:$G$1201=G22))} -> 745.08439 | U22: =ABS(I22-S22)/T22 -> 1.1347552 | V22: =IF(U22>3,"Yes","No") -> No
A23: ORD200273 | B23: 45592 | C23: =YEAR(B23) -> 2024 | D23: =TEXT(B23,"mmmm") -> October | E23: ="Q"&ROUNDUP(MONTH(B23)/3,0) -> Q4 | F23: C11849 | G23: Tablet | H23: 2 | I23: 238.25 | J23: 974 Main St | K23: Online | L23: Cancelled | M23: TRK91195261 | N23: 7 | O23: FREESHIP | P23: =IF(ISBLANK(O23),"NO COUPON",O23) -> FREESHIP | Q23: Email | R23: 476.5 | S23: =AVERAGEIF($G$2:$G$1201,G23,$R$2:$R$1201) -> 1042.2846 | T23: {=_xlfn.STDEV.P(_xlfn._xlws.FILTER($R$2:$R$1201,$G$2:$G$1201=G23))} -> 832.06806 | U23: =ABS(I23-S23)/T23 -> 0.96630874 | V23: =IF(U23>3,"Yes","No") -> No
A24: ORD201045 | B24: 45555 | C24: =YEAR(B24) -> 2024 | D24: =TEXT(B24,"mmmm") -> September | E24: ="Q"&ROUNDUP(MONTH(B24)/3,0) -> Q3 | F24: C11893 | G24: Laptop | H24: 5 | I24: 316.4 | J24: 671 Main St | K24: Gift Card | L24: Returned | M24: TRK72012758 | N24: 7 | P24: =IF(ISBLANK(O24),"NO COUPON",O24) -> NO COUPON | Q24: Email | R24: 1582 | S24: =AVERAGEIF($G$2:$G$1201,G24,$R$2:$R$1201) -> 1110.5582 | T24: {=_xlfn.STDEV.P(_xlfn._xlws.FILTER($R$2:$R$1201,$G$2:$G$1201=G24))} -> 859.60878 | U24: =ABS(I24-S24)/T24 -> 0.92385998 | V24: =IF(U24>3,"Yes","No") -> No
A25: ORD200408 | B25: 45658 | C25: =YEAR(B25) -> 2025 | D25: =TEXT(B25,"mmmm") -> January | E25: ="Q"&ROUNDUP(MONTH(B25)/3,0) -> Q1 | F25: C11906 | G25: Printer | H25: 3 | I25: 412.53 | J25: 536 Main St | K25: Online | L25: Pending | M25: TRK31140158 | N25: 6 | O25: WINTER15 | P25: =IF(ISBLANK(O25),"NO COUPON",O25) -> WINTER15 | Q25: Google | R25: 1237.59 | S25: =AVERAGEIF($G$2:$G$1201,G25,$R$2:$R$1201) -> 1080.7327 | T25: {=_xlfn.STDEV.P(_xlfn._xlws.FILTER($R$2:$R$1201,$G$2:$G$1201=G25))} -> 851.72194 | U25: =ABS(I25-S25)/T25 -> 0.78453145 | V25: =IF(U25>3,"Yes","No") -> No
A26: ORD200420 | B26: 45625 | C26: =YEAR(B26) -> 2024 | D26: =TEXT(B26,"mmmm") -> November | E26: ="Q"&ROUNDUP(MONTH(B26)/3,0) -> Q4 | F26: C11921 | G26: Phone | H26: 1 | I26: 452.7 | J26: 439 Main St | K26: Debit Card | L26: Shipped | M26: TRK91362635 | N26: 5 | O26: FREESHIP | P26: =IF(ISBLANK(O26),"NO COUPON",O26) -> FREESHIP | Q26: Instagram | R26: 452.7 | S26: =AVERAGEIF($G$2:$G$1201,G26,$R$2:$R$1201) -> 972.57942 | T26: {=_xlfn.STDEV.P(_xlfn._xlws.FILTER($R$2:$R$1201,$G$2:$G$1201=G26))} -> 756.87137 | U26: =ABS(I26-S26)/T26 -> 0.6868795 | V26: =IF(U26>3,"Yes","No") -> No
A27: ORD200489 | B27: 45174 | C27: =YEAR(B27) -> 2023 | D27: =TEXT(B27,"mmmm") -> September | E27: ="Q"&ROUNDUP(MONTH(B27)/3,0) -> Q3 | F27: C11940 | G27: Tablet | H27: 3 | I27: 149.34 | J27: 589 Main St | K27: Gift Card | L27: Cancelled | M27: TRK85466461 | N27: 7 | O27: WINTER15 | P27: =IF(ISBLANK(O27),"NO COUPON",O27) -> WINTER15 | Q27: Email | R27: 448.02 | S27: =AVERAGEIF($G$2:$G$1201,G27,$R$2:$R$1201) -> 1042.2846 | T27: {=_xlfn.STDEV.P(_xlfn._xlws.FILTER($R$2:$R$1201,$G$2:$G$1201=G27))} -> 832.06806 | U27: =ABS(I27-S27)/T27 -> 1.073163 | V27: =IF(U27>3,"Yes","No") -> No
A28: ORD200049 | B28: 45206 | C28: =YEAR(B28) -> 2023 | D28: =TEXT(B28,"mmmm") -> October | E28: ="Q"&ROUNDUP(MONTH(B28)/3,0) -> Q4 | F28: C11985 | G28: Printer | H28: 1 | I28: 30.44 | J28: 633 Main St | K28: Credit Card | L28: Shipped | M28: TRK53272402 | N28: 1 | O28: SAVE10 | P28: =IF(ISBLANK(O28),"NO COUPON",O28) -> SAVE10 | Q28: Email | R28: 30.44 | S28: =AVERAGEIF($G$2:$G$1201,G28,$R$2:$R$1201) -> 1080.7327 | T28: {=_xlfn.STDEV.P(_xlfn._xlws.FILTER($R$2:$R$1201,$G$2:$G$1201=G28))} -> 851.72194 | U28: =ABS(I28-S28)/T28 -> 1.2331403 | V28: =IF(U28>3,"Yes","No") -> No
A29: ORD201141 | B29: 45704 | C29: =YEAR(B29) -> 2025 | D29: =TEXT(B29,"mmmm") -> February | E29: ="Q"&ROUNDUP(MONTH(B29)/3,0) -> Q1 | F29: C11998 | G29: Chair | H29: 3 | I29: 498.66 | J29: 382 Main St | K29: Cash | L29: Cancelled | M29: TRK26707221 | N29: 6 | P29: =IF(ISBLANK(O29),"NO COUPON",O29) -> NO COUPON | Q29: Email | R29: 1495.98 | S29: =AVERAGEIF($G$2:$G$1201,G29,$R$2:$R$1201) -> 1098.9894 | T29: {=_xlfn.STDEV.P(_xlfn._xlws.FILTER($R$2:$R$1201,$G$2:$G$1201=G29))} -> 817.71888 | U29: =ABS(I29-S29)/T29 -> 0.73415131 | V29: =IF(U29>3,"Yes","No") -> No
A30: ORD200563 | B30: 45272 | C30: =YEAR(B30) -> 2023 | D30: =TEXT(B30,"mmmm") -> December | E30: ="Q"&ROUNDUP(MONTH(B30)/3,0) -> Q4 | F30: C12039 | G30: Laptop | H30: 1 | I30: 132.68 | J30: 844 Main St | K30: Debit Card | L30: Returned | M30: TRK68645763 | N30: 1 | O30: SAVE10 | P30: =IF(ISBLANK(O30),"NO COUPON",O30) -> SAVE10 | Q30: Referral | R30: 132.68 | S30: =AVERAGEIF($G$2:$G$1201,G30,$R$2:$R$1201) -> 1110.5582 | T30: {=_xlfn.STDEV.P(_xlfn._xlws.FILTER($R$2:$R$1201,$G$2:$G$1201=G30))} -> 859.60878 | U30: =ABS(I30-S30)/T30 -> 1.1375851 | V30: =IF(U30>3,"Yes","No") -> No
A31: ORD200260 | B31: 45063 | C31: =YEAR(B31) -> 2023 | D31: =TEXT(B31,"mmmm") -> May | E31: ="Q"&ROUNDUP(MONTH(B31)/3,0) -> Q2 | F31: C12245 | G31: Monitor | H31: 2 | I31: 407.79 | J31: 153 Main St | K31: Debit Card | L31: Shipped | M31: TRK22000463 | N31: 3 | P31: =IF(ISBLANK(O31),"NO COUPON",O31) -> NO COUPON | Q31: Google | R31: 815.58 | S31: =AVERAGEIF($G$2:$G$1201,G31,$R$2:$R$1201) -> 1077.616 | T31: {=_xlfn.STDEV.P(_xlfn._xlws.FILTER($R$2:$R$1201,$G$2:$G$1201=G31))} -> 847.57365 | U31: =ABS(I31-S31)/T31 -> 0.7902865 | V31: =IF(U31>3,"Yes","No") -> No
A32: ORD201052 | B32: 45180 | C32: =YEAR(B32) -> 2023 | D32: =TEXT(B32,"mmmm") -> September | E32: ="Q"&ROUNDUP(MONTH(B32)/3,0) -> Q3 | F32: C12301 | G32: Tablet | H32: 1 | I32: 531.74 | J32: 493 Main St | K32: Online | L32: Shipped | M32: TRK25145796 | N32: 1 | O32: WINTER15 | P32: =IF(ISBLANK(O32),"NO COUPON",O32) -> WINTER15 | Q32: Google | R32: 531.74 | S32: =AVERAGEIF($G$2:$G$1201,G32,$R$2:$R$1201) -> 1042.2846 | T32: {=_xlfn.STDEV.P(_xlfn._xlws.FILTER($R$2:$R$1201,$G$2:$G$1201=G32))} -> 832.06806 | U32: =ABS(I32-S32)/T32 -> 0.61358519 | V32: =IF(U32>3,"Yes","No") -> No
A33: ORD200032 | B33: 45047 | C33: =YEAR(B33) -> 2023 | D33: =TEXT(B33,"mmmm") -> May | E33: ="Q"&ROUNDUP(MONTH(B33)/3,0) -> Q2 | F33: C12388 | G33: Tablet | H33: 5 | I33: 536.72 | J33: 830 Main St | K33: Cash | L33: Delivered | M33: TRK99261395 | N33: 10 | P33: =IF(ISBLANK(O33),"NO COUPON",O33) -> NO COUPON | Q33: Email | R33: 2683.6 | S33: =AVERAGEIF($G$2:$G$1201,G33,$R$2:$R$1201) -> 1042.2846 | T33: {=_xlfn.STDEV.P(_xlfn._xlws.FILTER($R$2:$R$1201,$G$2:$G$1201=G33))} -> 832.06806 | U33: =ABS(I33-S33)/T33 -> 0.6076001 | V33: =IF(U33>3,"Yes","No") -> No
A34: ORD200048 | B34: 45164 | C34: =YEAR(B34) -> 2023 | D34: =TEXT(B34,"mmmm") -> August | E34: ="Q"&ROUNDUP(MONTH(B34)/3,0) -> Q3 | F34: C12408 | G34: Monitor | H34: 2 | I34: 80.77 | J34: 464 Main St | K34: Debit Card | L34: Shipped | M34: TRK38938858 | N34: 4 | P34: =IF(ISBLANK(O34),"NO COUPON",O34) -> NO COUPON | Q34: Google | R34: 161.54 | S34: =AVERAGEIF($G$2:$G$1201,G34,$R$2:$R$1201) -> 1077.616 | T34: {=_xlfn.STDEV.P(_xlfn._xlws.FILTER($R$2:$R$1201,$G$2:$G$1201=G34))} -> 847.57365 | U34: =ABS(I34-S34)/T34 -> 1.1761173 | V34: =IF(U34>3,"Yes","No") -> No
A35: ORD200386 | B35: 45044 | C35: =YEAR(B35) -> 2023 | D35: =TEXT(B35,"mmmm") -> April | E35: ="Q"&ROUNDUP(MONTH(B35)/3,0) -> Q2 | F35: C12421 | G35: Tablet | H35: 1 | I35: 93.02 | J35: 373 Main St | K35: Online | L35: Returned | M35: TRK32588504 | N35: 4 | P35: =IF(ISBLANK(O35),"NO COUPON",O35) -> NO COUPON | Q35: Email | R35: 93.02 | S35: =AVERAGEIF($G$2:$G$1201,G35,$R$2:$R$1201) -> 1042.2846 | T35: {=_xlfn.STDEV.P(_xlfn._xlws.FILTER($R$2:$R$1201,$G$2:$G$1201=G35))} -> 832.06806 | U35: =ABS(I35-S35)/T35 -> 1.1408497 | V35: =IF(U35>3,"Yes","No") -> No
A36: ORD200762 | B36: 45552 | C36: =YEAR(B36) -> 2024 | D36: =TEXT(B36,"mmmm") -> September | E36: ="Q"&ROUNDUP(MONTH(B36)/3,0) -> Q3 | F36: C12444 | G36: Phone | H36: 3 | I36: 76.96 | J36: 611 Main St | K36: Cash | L36: Returned | M36: TRK97621403 | N36: 8 | O36: FREESHIP | P36: =IF(ISBLANK(O36),"NO COUPON",O36) -> FREESHIP | Q36: Email | R36: 230.88 | S36: =AVERAGEIF($G$2:$G$1201,G36,$R$2:$R$1201) -> 972.57942 | T36: {=_xlfn.STDEV.P(_xlfn._xlws.FILTER($R$2:$R$1201,$G$2:$G$1201=G36))} -> 756.87137 | U36: =ABS(I36-S36)/T36 -> 1.1833179 | V36: =IF(U36>3,"Yes","No") -> No
A37: ORD200962 | B37: 45541 | C37: =YEAR(B37) -> 2024 | D37: =TEXT(B37,"mmmm") -> September | E37: ="Q"&ROUNDUP(MONTH(B37)/3,0) -> Q3 | F37: C12459 | G37: Phone | H37: 2 | I37: 142.08 | J37: 838 Main St | K37: Gift Card | L37: Delivered | M37: TRK30674085 | N37: 4 | O37: SAVE10 | P37: =IF(ISBLANK(O37),"NO COUPON",O37) -> SAVE10 | Q37: Referral | R37: 284.16 | S37: =AVERAGEIF($G$2:$G$1201,G37,$R$2:$R$1201) -> 972.57942 | T37: {=_xlfn.STDEV.P(_xlfn._xlws.FILTER($R$2:$R$1201,$G$2:$G$1201=G37))} -> 756.87137 | U37: =ABS(I37-S37)/T37 -> 1.0972795 | V37: =IF(U37>3,"Yes","No") -> No
A38: ORD201110 | B38: 45347 | C38: =YEAR(B38) -> 2024 | D38: =TEXT(B38,"mmmm") -> February | E38: ="Q"&ROUNDUP(MONTH(B38)/3,0) -> Q1 | F38: C12472 | G38: Chair | H38: 3 | I38: 84.31 | J38: 912 Main St | K38: Credit Card | L38: Shipped | M38: TRK36103184 | N38: 3 | O38: SAVE10 | P38: =IF(ISBLANK(O38),"NO COUPON",O38) -> SAVE10 | Q38: Email | R38: 252.93 | S38: =AVERAGEIF($G$2:$G$1201,G38,$R$2:$R$1201) -> 1098.9894 | T38: {=_xlfn.STDEV.P(_xlfn._xlws.FILTER($R$2:$R$1201,$G$2:$G$1201=G38))} -> 817.71888 | U38: =ABS(I38-S38)/T38 -> 1.2408658 | V38: =IF(U38>3,"Yes","No") -> No
A39: ORD200601 | B39: 45201 | C39: =YEAR(B39) -> 2023 | D39: =TEXT(B39,"mmmm") -> October | E39: ="Q"&ROUNDUP(MONTH(B39)/3,0) -> Q4 | F39: C12479 | G39: Monitor | H39: 5 | I39: 24.82 | J39: 529 Main St | K39: Credit Card | L39: Shipped | M39: TRK73935314 | N39: 10 | P39: =IF(ISBLANK(O39),"NO COUPON",O39) -> NO COUPON | Q39: Referral | R39: 124.1 | S39: =AVERAGEIF($G$2:$G$1201,G39,$R$2:$R$1201) -> 1077.616 | T39: {=_xlfn.STDEV.P(_xlfn._xlws.FILTER($R$2:$R$1201,$G$2:$G$1201=G39))} -> 847.57365 | U39: =ABS(I39-S39)/T39 -> 1.2421292 | V39: =IF(U39>3,"Yes","No") -> No
A40: ORD201105 | B40: 45299 | C40: =YEAR(B40) -> 2024 | D40: =TEXT(B40,"mmmm") -> January | E40: ="Q"&ROUNDUP(MONTH(B40)/3,0) -> Q1 | F40: C12487 | G40: Tablet | H40: 3 | I40: 475.69 | J40: 884 Main St | K40: Gift Card | L40: Cancelled | M40: TRK23324770 | N40: 3 | O40: FREESHIP | P40: =IF(ISBLANK(O40),"NO COUPON",O40) -> FREESHIP | Q40: Google | R40: 1427.07 | S40: =AVERAGEIF($G$2:$G$1201,G40,$R$2:$R$1201) -> 1042.2846 | T40: {=_xlfn.STDEV.P(_xlfn._xlws.FILTER($R$2:$R$1201,$G$2:$G$1201=G40))} -> 832.06806 | U40: =ABS(I40-S40)/T40 -> 0.68094746 | V40: =IF(U40>3,"Yes","No") -> No
...

Sheet IQR Outliers
A1: OrderID | B1: Date | C1: Year | D1: Month | E1: Quarter | F1: CustomerID | G1: Product | H1: Quantity | I1: UnitPrice | J1: ShippingAddress | K1: PaymentMethod | L1: OrderStatus | M1: TrackingNumber | N1: ItemsInCart | O1: CouponCode | P1: CouponCode2 | Q1: ReferralSource | R1: TotalPrice | S1: Outliers? | Y1: Q1 | Z1: =_xlfn.QUARTILE.INC(Table1[TotalPrice],1) -> 410.52
A2: ORD200853 | B2: 45215 | C2: =YEAR(B2) -> 2023 | D2: =TEXT(B2,"mmmm") -> October | E2: ="Q"&ROUNDUP(MONTH(B2)/3,0) -> Q4 | F2: C10002 | G2: Printer | H2: 3 | I2: 490.01 | J2: 894 Main St | K2: Cash | L2: Returned | M2: TRK94641152 | N2: 4 | O2: SAVE10 | P2: =IF(ISBLANK(O2),"NO COUPON",O2) -> SAVE10 | Q2: Facebook | R2: 1470.03 | S2: =IF(OR(R2>$Z$4,R2<Z5),"No","Yes") -> No | Y2: Q3 | Z2: =_xlfn.QUARTILE.INC(Table1[TotalPrice],3) -> 1578.475
A3: ORD200037 | B3: 45579 | C3: =YEAR(B3) -> 2024 | D3: =TEXT(B3,"mmmm") -> October | E3: ="Q"&ROUNDUP(MONTH(B3)/3,0) -> Q4 | F3: C10054 | G3: Laptop | H3: 2 | I3: 76.74 | J3: 409 Main St | K3: Cash | L3: Returned | M3: TRK94005261 | N3: 7 | O3: SAVE10 | P3: =IF(ISBLANK(O3),"NO COUPON",O3) -> SAVE10 | Q3: Instagram | R3: 153.48 | S3: =IF(OR(R3>$Z$4,R3<Z6),"No","Yes") -> No | Y3: IQR | Z3: =Z2-Z1 -> 1167.955
A4: ORD200201 | B4: 45095 | C4: =YEAR(B4) -> 2023 | D4: =TEXT(B4,"mmmm") -> June | E4: ="Q"&ROUNDUP(MONTH(B4)/3,0) -> Q2 | F4: C10126 | G4: Monitor | H4: 2 | I4: 674.9 | J4: 146 Main St | K4: Online | L4: Shipped | M4: TRK75607531 | N4: 4 | O4: SAVE10 | P4: =IF(ISBLANK(O4),"NO COUPON",O4) -> SAVE10 | Q4: Facebook | R4: 1349.8 | S4: =IF(OR(R4>$Z$4,R4<Z7),"No","Yes") -> No | Y4: Lower limit | Z4: =Z1-1.5*(Z3) -> -1341.4125
A5: ORD200728 | B5: 45502 | C5: =YEAR(B5) -> 2024 | D5: =TEXT(B5,"mmmm") -> July | E5: ="Q"&ROUNDUP(MONTH(B5)/3,0) -> Q3 | F5: C10154 | G5: Desk | H5: 4 | I5: 325.76 | J5: 827 Main St | K5: Gift Card | L5: Shipped | M5: TRK79793300 | N5: 8 | O5: WINTER15 | P5: =IF(ISBLANK(O5),"NO COUPON",O5) -> WINTER15 | Q5: Email | R5: 1303.04 | S5: =IF(OR(R5>$Z$4,R5<Z8),"No","Yes") -> No | Y5: Upper limit | Z5: =Z2+1.5*(Z3) -> 3330.4075
A6: ORD200991 | B6: 45421 | C6: =YEAR(B6) -> 2024 | D6: =TEXT(B6,"mmmm") -> May | E6: ="Q"&ROUNDUP(MONTH(B6)/3,0) -> Q2 | F6: C10211 | G6: Desk | H6: 5 | I6: 127.18 | J6: 598 Main St | K6: Debit Card | L6: Cancelled | M6: TRK68938335 | N6: 10 | O6: FREESHIP | P6: =IF(ISBLANK(O6),"NO COUPON",O6) -> FREESHIP | Q6: Google | R6: 635.9 | S6: =IF(OR(R6>$Z$4,R6<Z9),"No","Yes") -> No
A7: ORD201184 | B7: 45196 | C7: =YEAR(B7) -> 2023 | D7: =TEXT(B7,"mmmm") -> September | E7: ="Q"&ROUNDUP(MONTH(B7)/3,0) -> Q3 | F7: C10222 | G7: Laptop | H7: 1 | I7: 204.08 | J7: 979 Main St | K7: Gift Card | L7: Returned | M7: TRK86297895 | N7: 4 | P7: =IF(ISBLANK(O7),"NO COUPON",O7) -> NO COUPON | Q7: Google | R7: 204.08 | S7: =IF(OR(R7>$Z$4,R7<Z10),"No","Yes") -> No
A8: ORD200667 | B8: 45049 | C8: =YEAR(B8) -> 2023 | D8: =TEXT(B8,"mmmm") -> May | E8: ="Q"&ROUNDUP(MONTH(B8)/3,0) -> Q2 | F8: C10477 | G8: Laptop | H8: 1 | I8: 466.42 | J8: 172 Main St | K8: Gift Card | L8: Pending | M8: TRK41505339 | N8: 5 | O8: SAVE10 | P8: =IF(ISBLANK(O8),"NO COUPON",O8) -> SAVE10 | Q8: Email | R8: 466.42 | S8: =IF(OR(R8>$Z$4,R8<Z11),"No","Yes") -> No
A9: ORD200744 | B9: 45455 | C9: =YEAR(B9) -> 2024 | D9: =TEXT(B9,"mmmm") -> June | E9: ="Q"&ROUNDUP(MONTH(B9)/3,0) -> Q2 | F9: C10642 | G9: Tablet | H9: 2 | I9: 461.37 | J9: 200 Main St | K9: Cash | L9: Delivered | M9: TRK98725693 | N9: 5 | O9: SAVE10 | P9: =IF(ISBLANK(O9),"NO COUPON",O9) -> SAVE10 | Q9: Google | R9: 922.74 | S9: =IF(OR(R9>$Z$4,R9<Z12),"No","Yes") -> No
A10: ORD201055 | B10: 45222 | C10: =YEAR(B10) -> 2023 | D10: =TEXT(B10,"mmmm") -> October | E10: ="Q"&ROUNDUP(MONTH(B10)/3,0) -> Q4 | F10: C10787 | G10: Monitor | H10: 4 | I10: 274.82 | J10: 932 Main St | K10: Debit Card | L10: Delivered | M10: TRK91512567 | N10: 9 | O10: WINTER15 | P10: =IF(ISBLANK(O10),"NO COUPON",O10) -> WINTER15 | Q10: Email | R10: 1099.28 | S10: =IF(OR(R10>$Z$4,R10<Z13),"No","Yes") -> No
A11: ORD201066 | B11: 45280 | C11: =YEAR(B11) -> 2023 | D11: =TEXT(B11,"mmmm") -> December | E11: ="Q"&ROUNDUP(MONTH(B11)/3,0) -> Q4 | F11: C10791 | G11: Desk | H11: 1 | I11: 355.09 | J11: 674 Main St | K11: Debit Card | L11: Cancelled | M11: TRK20321248 | N11: 5 | O11: SAVE10 | P11: =IF(ISBLANK(O11),"NO COUPON",O11) -> SAVE10 | Q11: Instagram | R11: 355.09 | S11: =IF(OR(R11>$Z$4,R11<Z14),"No","Yes") -> No
A12: ORD200254 | B12: 45286 | C12: =YEAR(B12) -> 2023 | D12: =TEXT(B12,"mmmm") -> December | E12: ="Q"&ROUNDUP(MONTH(B12)/3,0) -> Q4 | F12: C10866 | G12: Monitor | H12: 3 | I12: 263.19 | J12: 770 Main St | K12: Online | L12: Delivered | M12: TRK34809583 | N12: 5 | P12: =IF(ISBLANK(O12),"NO COUPON",O12) -> NO COUPON | Q12: Instagram | R12: 789.57 | S12: =IF(OR(R12>$Z$4,R12<Z15),"No","Yes") -> No
A13: ORD200740 | B13: 45493 | C13: =YEAR(B13) -> 2024 | D13: =TEXT(B13,"mmmm") -> July | E13: ="Q"&ROUNDUP(MONTH(B13)/3,0) -> Q3 | F13: C10892 | G13: Desk | H13: 2 | I13: 377.47 | J13: 433 Main St | K13: Cash | L13: Pending | M13: TRK76154554 | N13: 7 | P13: =IF(ISBLANK(O13),"NO COUPON",O13) -> NO COUPON | Q13: Google | R13: 754.94 | S13: =IF(OR(R13>$Z$4,R13<Z16),"No","Yes") -> No
A14: ORD200859 | B14: 45532 | C14: =YEAR(B14) -> 2024 | D14: =TEXT(B14,"mmmm") -> August | E14: ="Q"&ROUNDUP(MONTH(B14)/3,0) -> Q3 | F14: C11127 | G14: Chair | H14: 5 | I14: 261.33 | J14: 154 Main St | K14: Credit Card | L14: Returned | M14: TRK73285507 | N14: 5 | O14: SAVE10 | P14: =IF(ISBLANK(O14),"NO COUPON",O14) -> SAVE10 | Q14: Referral | R14: 1306.65 | S14: =IF(OR(R14>$Z$4,R14<Z17),"No","Yes") -> No
A15: ORD200277 | B15: 45544 | C15: =YEAR(B15) -> 2024 | D15: =TEXT(B15,"mmmm") -> September | E15: ="Q"&ROUNDUP(MONTH(B15)/3,0) -> Q3 | F15: C11210 | G15: Chair | H15: 5 | I15: 90.92 | J15: 910 Main St | K15: Credit Card | L15: Delivered | M15: TRK44929965 | N15: 9 | O15: SAVE10 | P15: =IF(ISBLANK(O15),"NO COUPON",O15) -> SAVE10 | Q15: Facebook | R15: 454.6 | S15: =IF(OR(R15>$Z$4,R15<Z18),"No","Yes") -> No
A16: ORD200511 | B16: 45366 | C16: =YEAR(B16) -> 2024 | D16: =TEXT(B16,"mmmm") -> March | E16: ="Q"&ROUNDUP(MONTH(B16)/3,0) -> Q1 | F16: C11415 | G16: Monitor | H16: 5 | I16: 575.24 | J16: 267 Main St | K16: Cash | L16: Delivered | M16: TRK65061457 | N16: 7 | O16: WINTER15 | P16: =IF(ISBLANK(O16),"NO COUPON",O16) -> WINTER15 | Q16: Email | R16: 2876.2 | S16: =IF(OR(R16>$Z$4,R16<Z19),"No","Yes") -> No
A17: ORD201135 | B17: 45288 | C17: =YEAR(B17) -> 2023 | D17: =TEXT(B17,"mmmm") -> December | E17: ="Q"&ROUNDUP(MONTH(B17)/3,0) -> Q4 | F17: C11473 | G17: Printer | H17: 2 | I17: 73.41 | J17: 562 Main St | K17: Online | L17: Shipped | M17: TRK97793275 | N17: 2 | O17: SAVE10 | P17: =IF(ISBLANK(O17),"NO COUPON",O17) -> SAVE10 | Q17: Google | R17: 146.82 | S17: =IF(OR(R17>$Z$4,R17<Z20),"No","Yes") -> No
A18: ORD200193 | B18: 45128 | C18: =YEAR(B18) -> 2023 | D18: =TEXT(B18,"mmmm") -> July | E18: ="Q"&ROUNDUP(MONTH(B18)/3,0) -> Q3 | F18: C11644 | G18: Printer | H18: 1 | I18: 46.66 | J18: 429 Main St | K18: Cash | L18: Cancelled | M18: TRK81320339 | N18: 6 | P18: =IF(ISBLANK(O18),"NO COUPON",O18) -> NO COUPON | Q18: Google | R18: 46.66 | S18: =IF(OR(R18>$Z$4,R18<Z21),"No","Yes") -> No
A19: ORD200406 | B19: 45270 | C19: =YEAR(B19) -> 2023 | D19: =TEXT(B19,"mmmm") -> December | E19: ="Q"&ROUNDUP(MONTH(B19)/3,0) -> Q4 | F19: C11657 | G19: Tablet | H19: 4 | I19: 66.1 | J19: 572 Main St | K19: Cash | L19: Returned | M19: TRK50284486 | N19: 9 | O19: WINTER15 | P19: =IF(ISBLANK(O19),"NO COUPON",O19) -> WINTER15 | Q19: Google | R19: 264.4 | S19: =IF(OR(R19>$Z$4,R19<Z22),"No","Yes") -> No
A20: ORD200218 | B20: 45044 | C20: =YEAR(B20) -> 2023 | D20: =TEXT(B20,"mmmm") -> April | E20: ="Q"&ROUNDUP(MONTH(B20)/3,0) -> Q2 | F20: C11665 | G20: Tablet | H20: 3 | I20: 112.46 | J20: 882 Main St | K20: Gift Card | L20: Shipped | M20: TRK10993930 | N20: 6 | O20: SAVE10 | P20: =IF(ISBLANK(O20),"NO COUPON",O20) -> SAVE10 | Q20: Instagram | R20: 337.38 | S20: =IF(OR(R20>$Z$4,R20<Z23),"No","Yes") -> No
A21: ORD200504 | B21: 45819 | C21: =YEAR(B21) -> 2025 | D21: =TEXT(B21,"mmmm") -> June | E21: ="Q"&ROUNDUP(MONTH(B21)/3,0) -> Q2 | F21: C11676 | G21: Monitor | H21: 2 | I21: 464.5 | J21: 805 Main St | K21: Online | L21: Cancelled | M21: TRK35726395 | N21: 2 | O21: WINTER15 | P21: =IF(ISBLANK(O21),"NO COUPON",O21) -> WINTER15 | Q21: Instagram | R21: 929 | S21: =IF(OR(R21>$Z$4,R21<Z24),"No","Yes") -> No
A22: ORD200414 | B22: 45781 | C22: =YEAR(B22) -> 2025 | D22: =TEXT(B22,"mmmm") -> May | E22: ="Q"&ROUNDUP(MONTH(B22)/3,0) -> Q2 | F22: C11829 | G22: Desk | H22: 2 | I22: 139.57 | J22: 797 Main St | K22: Cash | L22: Delivered | M22: TRK84229257 | N22: 4 | O22: WINTER15 | P22: =IF(ISBLANK(O22),"NO COUPON",O22) -> WINTER15 | Q22: Facebook | R22: 279.14 | S22: =IF(OR(R22>$Z$4,R22<Z25),"No","Yes") -> No
A23: ORD200273 | B23: 45592 | C23: =YEAR(B23) -> 2024 | D23: =TEXT(B23,"mmmm") -> October | E23: ="Q"&ROUNDUP(MONTH(B23)/3,0) -> Q4 | F23: C11849 | G23: Tablet | H23: 2 | I23: 238.25 | J23: 974 Main St | K23: Online | L23: Cancelled | M23: TRK91195261 | N23: 7 | O23: FREESHIP | P23: =IF(ISBLANK(O23),"NO COUPON",O23) -> FREESHIP | Q23: Email | R23: 476.5 | S23: =IF(OR(R23>$Z$4,R23<Z26),"No","Yes") -> No
A24: ORD201045 | B24: 45555 | C24: =YEAR(B24) -> 2024 | D24: =TEXT(B24,"mmmm") -> September | E24: ="Q"&ROUNDUP(MONTH(B24)/3,0) -> Q3 | F24: C11893 | G24: Laptop | H24: 5 | I24: 316.4 | J24: 671 Main St | K24: Gift Card | L24: Returned | M24: TRK72012758 | N24: 7 | P24: =IF(ISBLANK(O24),"NO COUPON",O24) -> NO COUPON | Q24: Email | R24: 1582 | S24: =IF(OR(R24>$Z$4,R24<Z27),"No","Yes") -> No
A25: ORD200408 | B25: 45658 | C25: =YEAR(B25) -> 2025 | D25: =TEXT(B25,"mmmm") -> January | E25: ="Q"&ROUNDUP(MONTH(B25)/3,0) -> Q1 | F25: C11906 | G25: Printer | H25: 3 | I25: 412.53 | J25: 536 Main St | K25: Online | L25: Pending | M25: TRK31140158 | N25: 6 | O25: WINTER15 | P25: =IF(ISBLANK(O25),"NO COUPON",O25) -> WINTER15 | Q25: Google | R25: 1237.59 | S25: =IF(OR(R25>$Z$4,R25<Z28),"No","Yes") -> No
A26: ORD200420 | B26: 45625 | C26: =YEAR(B26) -> 2024 | D26: =TEXT(B26,"mmmm") -> November | E26: ="Q"&ROUNDUP(MONTH(B26)/3,0) -> Q4 | F26: C11921 | G26: Phone | H26: 1 | I26: 452.7 | J26: 439 Main St | K26: Debit Card | L26: Shipped | M26: TRK91362635 | N26: 5 | O26: FREESHIP | P26: =IF(ISBLANK(O26),"NO COUPON",O26) -> FREESHIP | Q26: Instagram | R26: 452.7 | S26: =IF(OR(R26>$Z$4,R26<Z29),"No","Yes") -> No
A27: ORD200489 | B27: 45174 | C27: =YEAR(B27) -> 2023 | D27: =TEXT(B27,"mmmm") -> September | E27: ="Q"&ROUNDUP(MONTH(B27)/3,0) -> Q3 | F27: C11940 | G27: Tablet | H27: 3 | I27: 149.34 | J27: 589 Main St | K27: Gift Card | L27: Cancelled | M27: TRK85466461 | N27: 7 | O27: WINTER15 | P27: =IF(ISBLANK(O27),"NO COUPON",O27) -> WINTER15 | Q27: Email | R27: 448.02 | S27: =IF(OR(R27>$Z$4,R27<Z30),"No","Yes") -> No
A28: ORD200049 | B28: 45206 | C28: =YEAR(B28) -> 2023 | D28: =TEXT(B28,"mmmm") -> October | E28: ="Q"&ROUNDUP(MONTH(B28)/3,0) -> Q4 | F28: C11985 | G28: Printer | H28: 1 | I28: 30.44 | J28: 633 Main St | K28: Credit Card | L28: Shipped | M28: TRK53272402 | N28: 1 | O28: SAVE10 | P28: =IF(ISBLANK(O28),"NO COUPON",O28) -> SAVE10 | Q28: Email | R28: 30.44 | S28: =IF(OR(R28>$Z$4,R28<Z31),"No","Yes") -> No
A29: ORD201141 | B29: 45704 | C29: =YEAR(B29) -> 2025 | D29: =TEXT(B29,"mmmm") -> February | E29: ="Q"&ROUNDUP(MONTH(B29)/3,0) -> Q1 | F29: C11998 | G29: Chair | H29: 3 | I29: 498.66 | J29: 382 Main St | K29: Cash | L29: Cancelled | M29: TRK26707221 | N29: 6 | P29: =IF(ISBLANK(O29),"NO COUPON",O29) -> NO COUPON | Q29: Email | R29: 1495.98 | S29: =IF(OR(R29>$Z$4,R29<Z32),"No","Yes") -> No
A30: ORD200563 | B30: 45272 | C30: =YEAR(B30) -> 2023 | D30: =TEXT(B30,"mmmm") -> December | E30: ="Q"&ROUNDUP(MONTH(B30)/3,0) -> Q4 | F30: C12039 | G30: Laptop | H30: 1 | I30: 132.68 | J30: 844 Main St | K30: Debit Card | L30: Returned | M30: TRK68645763 | N30: 1 | O30: SAVE10 | P30: =IF(ISBLANK(O30),"NO COUPON",O30) -> SAVE10 | Q30: Referral | R30: 132.68 | S30: =IF(OR(R30>$Z$4,R30<Z33),"No","Yes") -> No
A31: ORD200260 | B31: 45063 | C31: =YEAR(B31) -> 2023 | D31: =TEXT(B31,"mmmm") -> May | E31: ="Q"&ROUNDUP(MONTH(B31)/3,0) -> Q2 | F31: C12245 | G31: Monitor | H31: 2 | I31: 407.79 | J31: 153 Main St | K31: Debit Card | L31: Shipped | M31: TRK22000463 | N31: 3 | P31: =IF(ISBLANK(O31),"NO COUPON",O31) -> NO COUPON | Q31: Google | R31: 815.58 | S31: =IF(OR(R31>$Z$4,R31<Z34),"No","Yes") -> No
A32: ORD201052 | B32: 45180 | C32: =YEAR(B32) -> 2023 | D32: =TEXT(B32,"mmmm") -> September | E32: ="Q"&ROUNDUP(MONTH(B32)/3,0) -> Q3 | F32: C12301 | G32: Tablet | H32: 1 | I32: 531.74 | J32: 493 Main St | K32: Online | L32: Shipped | M32: TRK25145796 | N32: 1 | O32: WINTER15 | P32: =IF(ISBLANK(O32),"NO COUPON",O32) -> WINTER15 | Q32: Google | R32: 531.74 | S32: =IF(OR(R32>$Z$4,R32<Z35),"No","Yes") -> No
A33: ORD200032 | B33: 45047 | C33: =YEAR(B33) -> 2023 | D33: =TEXT(B33,"mmmm") -> May | E33: ="Q"&ROUNDUP(MONTH(B33)/3,0) -> Q2 | F33: C12388 | G33: Tablet | H33: 5 | I33: 536.72 | J33: 830 Main St | K33: Cash | L33: Delivered | M33: TRK99261395 | N33: 10 | P33: =IF(ISBLANK(O33),"NO COUPON",O33) -> NO COUPON | Q33: Email | R33: 2683.6 | S33: =IF(OR(R33>$Z$4,R33<Z36),"No","Yes") -> No
A34: ORD200048 | B34: 45164 | C34: =YEAR(B34) -> 2023 | D34: =TEXT(B34,"mmmm") -> August | E34: ="Q"&ROUNDUP(MONTH(B34)/3,0) -> Q3 | F34: C12408 | G34: Monitor | H34: 2 | I34: 80.77 | J34: 464 Main St | K34: Debit Card | L34: Shipped | M34: TRK38938858 | N34: 4 | P34: =IF(ISBLANK(O34),"NO COUPON",O34) -> NO COUPON | Q34: Google | R34: 161.54 | S34: =IF(OR(R34>$Z$4,R34<Z37),"No","Yes") -> No
A35: ORD200386 | B35: 45044 | C35: =YEAR(B35) -> 2023 | D35: =TEXT(B35,"mmmm") -> April | E35: ="Q"&ROUNDUP(MONTH(B35)/3,0) -> Q2 | F35: C12421 | G35: Tablet | H35: 1 | I35: 93.02 | J35: 373 Main St | K35: Online | L35: Returned | M35: TRK32588504 | N35: 4 | P35: =IF(ISBLANK(O35),"NO COUPON",O35) -> NO COUPON | Q35: Email | R35: 93.02 | S35: =IF(OR(R35>$Z$4,R35<Z38),"No","Yes") -> No
A36: ORD200762 | B36: 45552 | C36: =YEAR(B36) -> 2024 | D36: =TEXT(B36,"mmmm") -> September | E36: ="Q"&ROUNDUP(MONTH(B36)/3,0) -> Q3 | F36: C12444 | G36: Phone | H36: 3 | I36: 76.96 | J36: 611 Main St | K36: Cash | L36: Returned | M36: TRK97621403 | N36: 8 | O36: FREESHIP | P36: =IF(ISBLANK(O36),"NO COUPON",O36) -> FREESHIP | Q36: Email | R36: 230.88 | S36: =IF(OR(R36>$Z$4,R36<Z39),"No","Yes") -> No
A37: ORD200962 | B37: 45541 | C37: =YEAR(B37) -> 2024 | D37: =TEXT(B37,"mmmm") -> September | E37: ="Q"&ROUNDUP(MONTH(B37)/3,0) -> Q3 | F37: C12459 | G37: Phone | H37: 2 | I37: 142.08 | J37: 838 Main St | K37: Gift Card | L37: Delivered | M37: TRK30674085 | N37: 4 | O37: SAVE10 | P37: =IF(ISBLANK(O37),"NO COUPON",O37) -> SAVE10 | Q37: Referral | R37: 284.16 | S37: =IF(OR(R37>$Z$4,R37<Z40),"No","Yes") -> No
A38: ORD201110 | B38: 45347 | C38: =YEAR(B38) -> 2024 | D38: =TEXT(B38,"mmmm") -> February | E38: ="Q"&ROUNDUP(MONTH(B38)/3,0) -> Q1 | F38: C12472 | G38: Chair | H38: 3 | I38: 84.31 | J38: 912 Main St | K38: Credit Card | L38: Shipped | M38: TRK36103184 | N38: 3 | O38: SAVE10 | P38: =IF(ISBLANK(O38),"NO COUPON",O38) -> SAVE10 | Q38: Email | R38: 252.93 | S38: =IF(OR(R38>$Z$4,R38<Z41),"No","Yes") -> No
